Workbook

Sheet 가정
B2: DPS 성장 모델 — 가정 (v1, 첫 시안)
B3: ※ 부품 강화·룬 옵션은 아직 수치설계 전이라 이번 모델에서는 제외했습니다 (제외했다는 것 자체가 중요한 전제입니다 — 실제 DPS는 이보다 더 높을 것입니다).
B5: 트리 → 스탯 환산
B6: 깊이당 노드 수 | D6: 6
B7: 노드 스탯 환산계수 k (스탯증가량 = 1강비용 × k) | D7: 0.0252
B8: 스탯 5종 균등분배 비율 (주문력/민첩/마나/마나회복/지능) | D8: 0.2
B10: 전투 공식 계수
B11: 스킬 계수 — 등급1 (등급 전환마다 신규 스킬셋 해금, 등급당 50% 복리) | D11: 1 | F11: 등급당 성장률 | G11: 0.5
B12: 지능배율 공식: 1 + 지능/D12 | D12: 100
B13: 명중률 기본값 | D13: 0.9
B14: 명중률 최대 가산폭 | D14: 0.09
B15: 명중률 민첩 반감계수 (민첩/(민첩+D15)) | D15: 200
B16: 크리확률 기본값 | D16: 0.05
B17: 크리확률 최대 가산폭 | D17: 0.75
B18: 크리확률 민첩 반감계수 | D18: 300
B19: 크리티컬 피해 (룬 없음 기본값) | D19: 1.5
B20: 방어 관통 (룬 없음 기본값) | D20: 0
B21: 공격속도 배율 기본 가산폭 | D21: 2
B22: 공격속도 민첩 반감계수 | D22: 400
B23: GPU 히트수 기댓값 계수 (강화레벨당, 1+계수×레벨) | D23: 0.02
B24: 속성 상성 배율 (중립 가정) | D24: 1
B26: 페이싱 보정 배율 (랭크별, 수동 지정 — 목표 페이싱에 맞춘 역산값)
B27: 랭크1 배율 | D27: 6.93
B28: 랭크2 배율 | D28: 2.26
B29: 랭크3 배율 | D29: 1
B30: 랭크4 배율 | D30: 1.08
B31: 랭크5 배율 | D31: 1.23
B32: 랭크6 배율 | D32: 1.9
B33: 랭크7 배율 | D33: 1.2
B34: 랭크8 배율 | D34: 4.18
B35: 랭크9 배율 | D35: 6.39
B36: 랭크10 배율 | D36: 34.5
B39: 스킬 마나 소모 & 마나 회복 (마나풀 대비 %)
B40: 스킬 마나소모율 (최대마나 대비 %/회) | D40: 0.05
B41: 마나회복율 (최대마나 대비 %/초) | D41: 0.1
B43: 부품 기여 (등급별 기본치 × 강화 성장, 랭크별 가정 강화수준)
B44: 등급1 부품 기본치(1강) | D44: 10
B45: 등급별 기본치 성장 배율 | D45: 2.5
B46: 강화당 성장률 (%, 복리, 최대 25강) | D46: 0.08
B47: 가정 강화레벨 — 등급 첫 랭크 | D47: 8
...

Sheet 참조데이터
A1: 참조 데이터 (몬스터 스탯 / 트리 비용 워크북에서 가져온 값)
A2: ※ 두 워크북이 갱신되면 이 표도 수동으로 다시 채워야 합니다 (라이브 연결 아님).
A4: 랭크 | B4: 등급 | C4: 랭크 끝까지 누적 1강비용 합 | D4: 이 랭크만의 순수 소모 마석(1강기준) | E4: 파밍 타겟 몬스터 | F4: 타겟 HP | G4: 타겟 방어력 | H4: 등급 시작 HP(효율 앵커) | I4: 등급 시작 드랍최대치
A5: 1 | B5: 1 | C5: 698.1 | D5: 698.1 | E5: 티어5 (보스) | F5: 253.125 | G5: 7.3205 | H5: 50 | I5: 2
A6: 2 | B6: 1 | C6: 4814 | D6: 4115.9 | E6: 티어5 (보스) | F6: 253.125 | G6: 7.3205 | H6: 50 | I6: 2
A7: 3 | B7: 2 | C7: 5191.1 | D7: 377.1 | E7: 티어10 (보스) | F7: 6075 | G7: 14.08396 | H7: 379.6875 | I7: 3
A8: 4 | B8: 2 | C8: 12151.7 | D8: 6960.6 | E8: 티어10 (보스) | F8: 6075 | G8: 14.08396 | H8: 379.6875 | I8: 3
A9: 5 | B9: 3 | C9: 13081.7 | D9: 930 | E9: 티어14 (일반) | F9: 183768.75 | G9: 26.821494 | H9: 12150 | I9: 4.5
A10: 6 | B10: 3 | C10: 51769.7 | D10: 38688 | E10: 티어14 (일반) | F10: 183768.75 | G10: 26.821494 | H10: 12150 | I10: 4.5
A11: 7 | B11: 4 | C11: 53583 | D11: 1813.3 | E11: 티어18 (일반) | F11: 15287263 | G11: 57.934427 | H11: 505364.06 | I11: 6.75
A12: 8 | B12: 4 | C12: 189514.8 | D12: 135931.8 | E12: 티어18 (일반) | F12: 15287263 | G12: 57.934427 | H12: 505364.06 | I12: 6.75
A13: 9 | B13: 5 | C13: 192736.7 | D13: 3221.9 | E13: 티어22 (일반) | F13: 3913539300 | G13: 141.44147 | H13: 61149052 | I13: 10.125
A14: 10 | B14: 5 | C14: 601763.8 | D14: 409027.1 | E14: 티어22 (일반) | F14: 3913539300 | G14: 141.44147 | H14: 61149052 | I14: 10.125

Sheet 랭크별 DPS·TTK
A1: 랭크별 누적 스탯 → DPS → TTK
A3: 랭크 | B3: 등급 | C3: 트리 스탯 | D3: 부품 스탯 | E3: 룬 기댓값(%) | F3: 최종 스탯 | G3: 지능배율 | H3: 명중률 | I3: 크리확률 | J3: 공격속도배율(원본) | K3: 스킬마나소모 | L3: 초당마나회복 | M3: 가동률 | N3: 실효공격속도 | O3: 히트당 데미지 | P3: DPS | Q3: 타겟 HP | R3: TTK(초, 1마리) | S3: 효율(마석/HP) | T3: 페이싱보정배율 | U3: 순수소모마석(노드×강화 반영) | V3: 소요시간(시간)
A4: 1 | B4: =참조데이터!B5 -> 1 | C4: =가정!$D$6*가정!$D$7*참조데이터!C5*가정!$D$8 -> 21.110544 | D4: =가정!$D$44*가정!$D$45^(B4-1)*(1+가정!$D$46)^(8-1) -> 17.138243 | E4: 0 | F4: =(C4+D4)*(1+E4) -> 38.248787 | G4: =1+F4/가정!$D$12 -> 1.3824879 | H4: =가정!$D$13+가정!$D$14*(F4/(F4+가정!$D$15)) -> 0.91444872 | I4: =가정!$D$16+가정!$D$17*(F4/(F4+가정!$D$18)) -> 0.13480914 | J4: =1+가정!$D$21*(F4/(F4+가정!$D$22)) -> 1.1745528 | K4: =F4*가정!$D$40 -> 1.9124393 | L4: =F4*가정!$D$41 -> 3.8248787 | M4: =MIN(1,L4/(K4*J4)) -> 1 | N4: =J4*M4 -> 1.1745528 | O4: =가정!$D$11*(1+가정!$G$11)^(B4-1)*F4*G4*(1+I4*(가정!$D$19-1))*가정!$D$24*(100/(100+참조데이터!G5-가정!$D$20)) -> 52.592687 | P4: =O4*N4*H4*(1+가정!$D$23*8) -> 65.526244 | Q4: =참조데이터!F5 -> 253.125 | R4: =Q4/P4 -> 3.8629561 | S4: =참조데이터!I5/(2*참조데이터!H5) -> 0.02 | T4: =가정!$D$27 -> 6.93 | U4: =참조데이터!D5*가정!$D$6*19.84 -> 83101.824 | V4: =U4/(S4*P4*T4)/3600 -> 2.5417308
A5: 2 | B5: =참조데이터!B6 -> 1 | C5: =가정!$D$6*가정!$D$7*참조데이터!C6*가정!$D$8 -> 145.57536 | D5: =가정!$D$44*가정!$D$45^(B5-1)*(1+가정!$D$46)^(20-1) -> 43.157011 | E5: 0 | F5: =(C5+D5)*(1+E5) -> 188.73237 | G5: =1+F5/가정!$D$12 -> 2.8873237 | H5: =가정!$D$13+가정!$D$14*(F5/(F5+가정!$D$15)) -> 0.94369565 | I5: =가정!$D$16+가정!$D$17*(F5/(F5+가정!$D$18)) -> 0.33962534 | J5: =1+가정!$D$21*(F5/(F5+가정!$D$22)) -> 1.6411483 | K5: =F5*가정!$D$40 -> 9.4366185 | L5: =F5*가정!$D$41 -> 18.873237 | M5: =MIN(1,L5/(K5*J5)) -> 1 | N5: =J5*M5 -> 1.6411483 | O5: =가정!$D$11*(1+가정!$G$11)^(B5-1)*F5*G5*(1+I5*(가정!$D$19-1))*가정!$D$24*(100/(100+참조데이터!G6-가정!$D$20)) -> 593.98504 | P5: =O5*N5*H5*(1+가정!$D$23*20) -> 1287.9035 | Q5: =참조데이터!F6 -> 253.125 | R5: =Q5/P5 -> 0.19654035 | S5: =참조데이터!I6/(2*참조데이터!H6) -> 0.02 | T5: =가정!$D$28 -> 2.26 | U5: =참조데이터!D6*가정!$D$6*19.84 -> 489956.74 | V5: =U5/(S5*P5*T5)/3600 -> 2.3379407
A6: 3 | B6: =참조데이터!B7 -> 2 | C6: =가정!$D$6*가정!$D$7*참조데이터!C7*가정!$D$8 -> 156.97886 | D6: =가정!$D$44*가정!$D$45^(B6-1)*(1+가정!$D$46)^(8-1) -> 42.845607 | E6: 0 | F6: =(C6+D6)*(1+E6) -> 199.82447 | G6: =1+F6/가정!$D$12 -> 2.9982447 | H6: =가정!$D$13+가정!$D$14*(F6/(F6+가정!$D$15)) -> 0.94498024 | I6: =가정!$D$16+가정!$D$17*(F6/(F6+가정!$D$18)) -> 0.34984197 | J6: =1+가정!$D$21*(F6/(F6+가정!$D$22)) -> 1.6662765 | K6: =F6*가정!$D$40 -> 9.9912235 | L6: =F6*가정!$D$41 -> 19.982447 | M6: =MIN(1,L6/(K6*J6)) -> 1 | N6: =J6*M6 -> 1.6662765 | O6: =가정!$D$11*(1+가정!$G$11)^(B6-1)*F6*G6*(1+I6*(가정!$D$19-1))*가정!$D$24*(100/(100+참조데이터!G7-가정!$D$20)) -> 925.53123 | P6: =O6*N6*H6*(1+가정!$D$23*8) -> 1690.5144 | Q6: =참조데이터!F7 -> 6075 | R6: =Q6/P6 -> 3.5935808 | S6: =참조데이터!I7/(2*참조데이터!H7) -> 0.0039506173 | T6: =가정!$D$29 -> 1 | U6: =참조데이터!D7*가정!$D$6*19.84 -> 44889.984 | V6: =U6/(S6*P6*T6)/3600 -> 1.8670809
A7: 4 | B7: =참조데이터!B8 -> 2 | C7: =가정!$D$6*가정!$D$7*참조데이터!C8*가정!$D$8 -> 367.46741 | D7: =가정!$D$44*가정!$D$45^(B7-1)*(1+가정!$D$46)^(20-1) -> 107.89253 | E7: 0 | F7: =(C7+D7)*(1+E7) -> 475.35993 | G7: =1+F7/가정!$D$12 -> 5.7535993 | H7: =가정!$D$13+가정!$D$14*(F7/(F7+가정!$D$15)) -> 0.96334755 | I7: =가정!$D$16+가정!$D$17*(F7/(F7+가정!$D$18)) -> 0.50981219 | J7: =1+가정!$D$21*(F7/(F7+가정!$D$22)) -> 2.0860902 | K7: =F7*가정!$D$40 -> 23.767997 | L7: =F7*가정!$D$41 -> 47.535993 | M7: =MIN(1,L7/(K7*J7)) -> 0.9587313 | N7: =J7*M7 -> 2 | O7: =가정!$D$11*(1+가정!$G$11)^(B7-1)*F7*G7*(1+I7*(가정!$D$19-1))*가정!$D$24*(100/(100+참조데이터!G8-가정!$D$20)) -> 4512.7377 | P7: =O7*N7*H7*(1+가정!$D$23*20) -> 12172.537 | Q7: =참조데이터!F8 -> 6075 | R7: =Q7/P7 -> 0.49907425 | S7: =참조데이터!I8/(2*참조데이터!H8) -> 0.0039506173 | T7: =가정!$D$30 -> 1.08 | U7: =참조데이터!D8*가정!$D$6*19.84 -> 828589.82 | V7: =U7/(S7*P7*T7)/3600 -> 4.4316685
A8: 5 | B8: =참조데이터!B9 -> 3 | C8: =가정!$D$6*가정!$D$7*참조데이터!C9*가정!$D$8 -> 395.59061 | D8: =가정!$D$44*가정!$D$45^(B8-1)*(1+가정!$D$46)^(8-1) -> 107.11402 | E8: 0 | F8: =(C8+D8)*(1+E8) -> 502.70462 | G8: =1+F8/가정!$D$12 -> 6.0270462 | H8: =가정!$D$13+가정!$D$14*(F8/(F8+가정!$D$15)) -> 0.96438469 | I8: =가정!$D$16+가정!$D$17*(F8/(F8+가정!$D$18)) -> 0.51969764 | J8: =1+가정!$D$21*(F8/(F8+가정!$D$22)) -> 2.1137743 | K8: =F8*가정!$D$40 -> 25.135231 | L8: =F8*가정!$D$41 -> 50.270462 | M8: =MIN(1,L8/(K8*J8)) -> 0.94617479 | N8: =J8*M8 -> 2 | O8: =가정!$D$11*(1+가정!$G$11)^(B8-1)*F8*G8*(1+I8*(가정!$D$19-1))*가정!$D$24*(100/(100+참조데이터!G9-가정!$D$20)) -> 6772.1332 | P8: =O8*N8*H8*(1+가정!$D$23*8) -> 15151.784 | Q8: =참조데이터!F9 -> 183768.75 | R8: =Q8/P8 -> 12.128522 | S8: =참조데이터!I9/(2*참조데이터!H9) -> 0.00018518519 | T8: =가정!$D$31 -> 1.23 | U8: =참조데이터!D9*가정!$D$6*19.84 -> 110707.2 | V8: =U8/(S8*P8*T8)/3600 -> 8.9104212
A9: 6 | B9: =참조데이터!B10 -> 3 | C9: =가정!$D$6*가정!$D$7*참조데이터!C10*가정!$D$8 -> 1565.5157 | D9: =가정!$D$44*가정!$D$45^(B9-1)*(1+가정!$D$46)^(20-1) -> 269.73132 | E9: =가정!$D$51 -> 0.05 | F9: =(C9+D9)*(1+E9) -> 1927.0094 | G9: =1+F9/가정!$D$12 -> 20.270094 | H9: =가정!$D$13+가정!$D$14*(F9/(F9+가정!$D$15)) -> 0.98153741 | I9: =가정!$D$16+가정!$D$17*(F9/(F9+가정!$D$18)) -> 0.69896765 | J9: =1+가정!$D$21*(F9/(F9+가정!$D$22)) -> 2.6562111 | K9: =F9*가정!$D$40 -> 96.35047 | L9: =F9*가정!$D$41 -> 192.70094 | M9: =MIN(1,L9/(K9*J9)) -> 0.7529522 | N9: =J9*M9 -> 2 | O9: =가정!$D$11*(1+가정!$G$11)^(B9-1)*F9*G9*(1+I9*(가정!$D$19-1))*가정!$D$24*(100/(100+참조데이터!G10-가정!$D$20)) -> 93518.37 | P9: =O9*N9*H9*(1+가정!$D$23*20) -> 257016.98 | Q9: =참조데이터!F10 -> 183768.75 | R9: =Q9/P9 -> 0.71500625 | S9: =참조데이터!I10/(2*참조데이터!H10) -> 0.00018518519 | T9: =가정!$D$32 -> 1.9 | U9: =참조데이터!D10*가정!$D$6*19.84 -> 4605419.5 | V9: =U9/(S9*P9*T9)/3600 -> 14.146371
A10: 7 | B10: =참조데이터!B11 -> 4 | C10: =가정!$D$6*가정!$D$7*참조데이터!C11*가정!$D$8 -> 1620.3499 | D10: =가정!$D$44*가정!$D$45^(B10-1)*(1+가정!$D$46)^(8-1) -> 267.78504 | E10: =가정!$D$52 -> 0.058 | F10: =(C10+D10)*(1+E10) -> 1997.6468 | G10: =1+F10/가정!$D$12 -> 20.976468 | H10: =가정!$D$13+가정!$D$14*(F10/(F10+가정!$D$15)) -> 0.98180942 | I10: =가정!$D$16+가정!$D$17*(F10/(F10+가정!$D$18)) -> 0.70207372 | J10: =1+가정!$D$21*(F10/(F10+가정!$D$22)) -> 2.6663395 | K10: =F10*가정!$D$40 -> 99.882339 | L10: =F10*가정!$D$41 -> 199.76468 | M10: =MIN(1,L10/(K10*J10)) -> 0.75009202 | N10: =J10*M10 -> 2 | O10: =가정!$D$11*(1+가정!$G$11)^(B10-1)*F10*G10*(1+I10*(가정!$D$19-1))*가정!$D$24*(100/(100+참조데이터!G11-가정!$D$20)) -> 120980.46 | P10: =O10*N10*H10*(1+가정!$D$23*8) -> 275569.03 | Q10: =참조데이터!F11 -> 15287263 | R10: =Q10/P10 -> 55.475257 | S10: =참조데이터!I11/(2*참조데이터!H11) -> 6.6783538e-06 | T10: =가정!$D$33 -> 1.2 | U10: =참조데이터!D11*가정!$D$6*19.84 -> 215855.23 | V10: =U10/(S10*P10*T10)/3600 -> 27.150573
A11: 8 | B11: =참조데이터!B12 -> 4 | C11: =가정!$D$6*가정!$D$7*참조데이터!C12*가정!$D$8 -> 5730.9276 | D11: =가정!$D$44*가정!$D$45^(B11-1)*(1+가정!$D$46)^(20-1) -> 674.32829 | E11: =가정!$D$53 -> 0.082 | F11: =(C11+D11)*(1+E11) -> 6930.4868 | G11: =1+F11/가정!$D$12 -> 70.304868 | H11: =가정!$D$13+가정!$D$14*(F11/(F11+가정!$D$15)) -> 0.98747563 | I11: =가정!$D$16+가정!$D$17*(F11/(F11+가정!$D$18)) -> 0.76888176 | J11: =1+가정!$D$21*(F11/(F11+가정!$D$22)) -> 2.8908667 | K11: =F11*가정!$D$40 -> 346.52434 | L11: =F11*가정!$D$41 -> 693.04868 | M11: =MIN(1,L11/(K11*J11)) -> 0.69183404 | N11: =J11*M11 -> 2 | O11: =가정!$D$11*(1+가정!$G$11)^(B11-1)*F11*G11*(1+I11*(가정!$D$19-1))*가정!$D$24*(100/(100+참조데이터!G12-가정!$D$20)) -> 1441519.5 | P11: =O11*N11*H11*(1+가정!$D$23*20) -> 3985703.1 | Q11: =참조데이터!F12 -> 15287263 | R11: =Q11/P11 -> 3.8355248 | S11: =참조데이터!I12/(2*참조데이터!H12) -> 6.6783538e-06 | T11: =가정!$D$34 -> 4.18 | U11: =참조데이터!D12*가정!$D$6*19.84 -> 16181321 | V11: =U11/(S11*P11*T11)/3600 -> 40.398091
A12: 9 | B12: =참조데이터!B13 -> 5 | C12: =가정!$D$6*가정!$D$7*참조데이터!C13*가정!$D$8 -> 5828.3578 | D12: =가정!$D$44*가정!$D$45^(B12-1)*(1+가정!$D$46)^(8-1) -> 669.4626 | E12: =가정!$D$54 -> 0.097 | F12: =(C12+D12)*(1+E12) -> 7128.109 | G12: =1+F12/가정!$D$12 -> 72.28109 | H12: =가정!$D$13+가정!$D$14*(F12/(F12+가정!$D$15)) -> 0.9875437 | I12: =가정!$D$16+가정!$D$17*(F12/(F12+가정!$D$18)) -> 0.76970965 | J12: =1+가정!$D$21*(F12/(F12+가정!$D$22)) -> 2.8937316 | K12: =F12*가정!$D$40 -> 356.40545 | L12: =F12*가정!$D$41 -> 712.8109 | M12: =MIN(1,L12/(K12*J12)) -> 0.6911491 | N12: =J12*M12 -> 2 | O12: =가정!$D$11*(1+가정!$G$11)^(B12-1)*F12*G12*(1+I12*(가정!$D$19-1))*가정!$D$24*(100/(100+참조데이터!G13-가정!$D$20)) -> 1496085.6 | P12: =O12*N12*H12*(1+가정!$D$23*8) -> 3427683.8 | Q12: =참조데이터!F13 -> 3913539300 | R12: =Q12/P12 -> 1141.7446 | S12: =참조데이터!I13/(2*참조데이터!H13) -> 8.278951e-08 | T12: =가정!$D$35 -> 6.39 | U12: =참조데이터!D13*가정!$D$6*19.84 -> 383534.98 | V12: =U12/(S12*P12*T12)/3600 -> 58.752392
A13: 10 | B13: =참조데이터!B14 -> 5 | C13: =가정!$D$6*가정!$D$7*참조데이터!C14*가정!$D$8 -> 18197.337 | D13: =가정!$D$44*가정!$D$45^(B13-1)*(1+가정!$D$46)^(20-1) -> 1685.8207 | E13: =가정!$D$55 -> 0.128 | F13: =(C13+D13)*(1+E13) -> 22428.202 | G13: =1+F13/가정!$D$12 -> 225.28202 | H13: =가정!$D$13+가정!$D$14*(F13/(F13+가정!$D$15)) -> 0.98920453 | I13: =가정!$D$16+가정!$D$17*(F13/(F13+가정!$D$18)) -> 0.7901004 | J13: =1+가정!$D$21*(F13/(F13+가정!$D$22)) -> 2.9649556 | K13: =F13*가정!$D$40 -> 1121.4101 | L13: =F13*가정!$D$41 -> 2242.8202 | M13: =MIN(1,L13/(K13*J13)) -> 0.67454635 | N13: =J13*M13 -> 2 | O13: =가정!$D$11*(1+가정!$G$11)^(B13-1)*F13*G13*(1+I13*(가정!$D$19-1))*가정!$D$24*(100/(100+참조데이터!G14-가정!$D$20)) -> 14779645 | P13: =O13*N13*H13*(1+가정!$D$23*20) -> 40936257 | Q13: =참조데이터!F14 -> 3913539300 | R13: =Q13/P13 -> 95.600809 | S13: =참조데이터!I14/(2*참조데이터!H14) -> 8.278951e-08 | T13: =가정!$D$36 -> 34.5 | U13: =참조데이터!D14*가정!$D$6*19.84 -> 48690586 | V13: =U13/(S13*P13*T13)/3600 -> 115.67512
A15: 해석: V열(소요시간)이 이 시트의 핵심 결과입니다. F열(최종 스탯)은 트리+부품 합산에 룬 기댓값을 곱한 값입니다. D열(부품 스탯)은 랭크1에서 트리 스탯 대비 비중이 가장 크고(최대 +70%대), 후반으로 갈수록 트리가 압도하며 비중이 줄어듭니다. E열(룬 기댓값)은 랭크6부터 반영되며 랭크10에 약 12.8%까지 커집니다. M열(가동률)은 초반 100%였다가 후반부(랭크6+)엔 약 67~70%에서 영원히 고정됩니다. T열(페이싱보정배율)은 랭크별로 직접 지정한 값으로, 목표 페이싱(랭크0~3은 2~3시간, 이후 점진 감속, 총 12일)에 맞춰 역산했습니다. 랭크0(2시간, 튜토리얼)을 더한 전체 합계는 약 286.8시간(11.95일)입니다. k=0.0252(부품·룬·GPU히트수 전부 반영 후 최종값).
